<!DOCTYPE HTML PUBLIC "-//W3C//DTD HTML 3.2//EN">
<HTML>
 <HEAD>
   <TITLE> [Mono-bugs] [Bug 419634] catch(Exception){throw; } within a catch block is throwing the previous exception
   </TITLE>
   <LINK REL="Index" HREF="index.html" >
   <LINK REL="made" HREF="mailto:mono-bugs%40lists.ximian.com?Subject=%5BMono-bugs%5D%20%5BBug%20419634%5D%20catch%28Exception%29%7Bthrow%3B%0A%20%7D%20within%20a%20catch%20block%20is%20throwing%20the%20previous%20exception&In-Reply-To=bug-419634-28286%40https.bugzilla.novell.com/">
   <META NAME="robots" CONTENT="index,nofollow">
   <META http-equiv="Content-Type" content="text/html; charset=us-ascii">
   <LINK REL="Previous"  HREF="078390.html">
   <LINK REL="Next"  HREF="078392.html">
 </HEAD>
 <BODY BGCOLOR="#ffffff">
   <H1>[Mono-bugs] [Bug 419634] catch(Exception){throw; } within a catch block is throwing the previous exception</H1>
    <B>bugzilla_noreply at novell.com</B> 
    <A HREF="mailto:mono-bugs%40lists.ximian.com?Subject=%5BMono-bugs%5D%20%5BBug%20419634%5D%20catch%28Exception%29%7Bthrow%3B%0A%20%7D%20within%20a%20catch%20block%20is%20throwing%20the%20previous%20exception&In-Reply-To=bug-419634-28286%40https.bugzilla.novell.com/"
       TITLE="[Mono-bugs] [Bug 419634] catch(Exception){throw; } within a catch block is throwing the previous exception">bugzilla_noreply at novell.com
       </A><BR>
    <I>Fri Aug 22 14:59:46 EDT 2008</I>
    <P><UL>
        <LI>Previous message: <A HREF="078390.html">[Mono-bugs] [Bug 419634] New: catch(Exception){throw; } within a catch block is throwing the previous exception
</A></li>
        <LI>Next message: <A HREF="078392.html">[Mono-bugs] [Bug 419634] catch(Exception){throw; } within a catch block is throwing the previous exception
</A></li>
         <LI> <B>Messages sorted by:</B> 
              <a href="date.html#78391">[ date ]</a>
              <a href="thread.html#78391">[ thread ]</a>
              <a href="subject.html#78391">[ subject ]</a>
              <a href="author.html#78391">[ author ]</a>
         </LI>
       </UL>
    <HR>  
<!--beginarticle-->
<PRE><A HREF="https://bugzilla.novell.com/show_bug.cgi?id=419634">https://bugzilla.novell.com/show_bug.cgi?id=419634</A>

User <A HREF="http://lists.ximian.com/mailman/listinfo/mono-bugs">rajneeshpatel at gmail.com</A> added comment
<A HREF="https://bugzilla.novell.com/show_bug.cgi?id=419634#c1">https://bugzilla.novell.com/show_bug.cgi?id=419634#c1</A>





--- Comment #1 from Raj Patel &lt;<A HREF="http://lists.ximian.com/mailman/listinfo/mono-bugs">rajneeshpatel at gmail.com</A>&gt;  2008-08-22 12:59:45 MDT ---
Created an attachment (id=235030)
 --&gt; (<A HREF="https://bugzilla.novell.com/attachment.cgi?id=235030">https://bugzilla.novell.com/attachment.cgi?id=235030</A>)
Test Case Program

This is a console app which reproduces the issue


-- 
Configure bugmail: <A HREF="https://bugzilla.novell.com/userprefs.cgi?tab=email">https://bugzilla.novell.com/userprefs.cgi?tab=email</A>
------- You are receiving this mail because: -------
You are the QA contact for the bug.
You are the assignee for the bug.
</PRE>













































<!--endarticle-->
    <HR>
    <P><UL>
        <!--threads-->
	<LI>Previous message: <A HREF="078390.html">[Mono-bugs] [Bug 419634] New: catch(Exception){throw; } within a catch block is throwing the previous exception
</A></li>
	<LI>Next message: <A HREF="078392.html">[Mono-bugs] [Bug 419634] catch(Exception){throw; } within a catch block is throwing the previous exception
</A></li>
         <LI> <B>Messages sorted by:</B> 
              <a href="date.html#78391">[ date ]</a>
              <a href="thread.html#78391">[ thread ]</a>
              <a href="subject.html#78391">[ subject ]</a>
              <a href="author.html#78391">[ author ]</a>
         </LI>
       </UL>

<hr>
<a href="http://lists.ximian.com/mailman/listinfo/mono-bugs">More information about the mono-bugs
mailing list</a><br>
</body></html>
