<!DOCTYPE HTML PUBLIC "-//W3C//DTD HTML 4.01 Transitional//EN">
<HTML>
 <HEAD>
   <TITLE> [Mono-list] Null task exception when doing ContinueWith
   </TITLE>
   <LINK REL="Index" HREF="index.html" >
   <LINK REL="made" HREF="mailto:mono-list%40lists.ximian.com?Subject=Re%3A%20%5BMono-list%5D%20Null%20task%20exception%20when%20doing%20ContinueWith&In-Reply-To=%3CCALwbK7RKhSASdLLJYKWf%3DB1pzrUNJaaTeXvFwLVanDoqByWBfw%40mail.gmail.com%3E">
   <META NAME="robots" CONTENT="index,nofollow">
   <style type="text/css">
       pre {
           white-space: pre-wrap;       /* css-2.1, curent FF, Opera, Safari */
           }
   </style>
   <META http-equiv="Content-Type" content="text/html; charset=us-ascii">
   
   <LINK REL="Next"  HREF="050889.html">
 </HEAD>
 <BODY BGCOLOR="#ffffff">
   <H1>[Mono-list] Null task exception when doing ContinueWith</H1>
    <B>Giuliano Barberi</B> 
    <A HREF="mailto:mono-list%40lists.ximian.com?Subject=Re%3A%20%5BMono-list%5D%20Null%20task%20exception%20when%20doing%20ContinueWith&In-Reply-To=%3CCALwbK7RKhSASdLLJYKWf%3DB1pzrUNJaaTeXvFwLVanDoqByWBfw%40mail.gmail.com%3E"
       TITLE="[Mono-list] Null task exception when doing ContinueWith">gbarberi at aotaonline.com
       </A><BR>
    <I>Fri May  2 11:17:10 UTC 2014</I>
    <P><UL>
        
        <LI>Next message: <A HREF="050889.html">[Mono-list] Null task exception when doing ContinueWith
</A></li>
         <LI> <B>Messages sorted by:</B> 
              <a href="date.html#50888">[ date ]</a>
              <a href="thread.html#50888">[ thread ]</a>
              <a href="subject.html#50888">[ subject ]</a>
              <a href="author.html#50888">[ author ]</a>
         </LI>
       </UL>
    <HR>  
<!--beginarticle-->
<PRE>Hey guys I'm seeing something strange. It could totally be user error but I
can't seem to figure it out.

I am doing this on some tasks that I never await in order to get the
exception:
        public static Task CatchUnhandledException(this Task task)
        {
            return task.ContinueWith(continuation =&gt;

Engine.UnhandledExceptionHandler(continuation.Exception),
                              TaskContinuationOptions.ExecuteSynchronously
|<i> TaskContinuationOptions.OnlyOnFaulted);
</I>        }

and the Engine.UnhandledExceptionHandler just logs the exception.

What's strange is that the exception is null and also doing
an Environment.StackTrace in the handler also yields nothing. I do have
--debug with the mdb files so I would suspect to get the full stacktrace. I
never saw this issue when I was running on .NET runtime but I also have
added more async code since so I'm not sure if it's something with Mono or
my app. I just can't find anything online and the documentation for Tasks
says that if it's faulted state there will be an exception.

Regards
-- 
Giuliano Barberi
-------------- next part --------------
An HTML attachment was scrubbed...
URL: &lt;<A HREF="http://lists.ximian.com/pipermail/mono-list/attachments/20140502/3589eaeb/attachment.html">http://lists.ximian.com/pipermail/mono-list/attachments/20140502/3589eaeb/attachment.html</A>&gt;
</PRE>


<!--endarticle-->
    <HR>
    <P><UL>
        <!--threads-->
	
	<LI>Next message: <A HREF="050889.html">[Mono-list] Null task exception when doing ContinueWith
</A></li>
         <LI> <B>Messages sorted by:</B> 
              <a href="date.html#50888">[ date ]</a>
              <a href="thread.html#50888">[ thread ]</a>
              <a href="subject.html#50888">[ subject ]</a>
              <a href="author.html#50888">[ author ]</a>
         </LI>
       </UL>

<hr>
<a href="http://lists.ximian.com/mailman/listinfo/mono-list">More information about the Mono-list
mailing list</a><br>
</body></html>
